<!-- NOTE: the joint limits and references have not been set. If using -->
<!-- this to control a real ur5, make sure they align with the values -->
<!-- used in the real arm firmware -->
<!-- Masses and center-of-masses taken from: www.universal-robots.com/
        how-tos-and-faqs/faq/ur-faq/
        parameters-for-calculations-of-kinematics-and-dynamics-45257/ -->
<!-- Principle moments of inertia not provided, set all to 0.1. -->
<!-- Inertia parameters provided at link below, not sure of accuracy so not used:
        http://hades.mech.northwestern.edu/images/4/49/UR5-URDF.pdf -->
<mujoco model="ur5">
    <compiler angle="radian" meshdir="meshes" balanceinertia="true"/>

    <default>
        <light castshadow="false" diffuse="1 1 1" />
        <camera fovy="60" />
    </default>

    <custom>
        <numeric name="START_ANGLES" data="0 -.67 -.67 0 0 0"/>
        <numeric name="N_GRIPPER_JOINTS" data="0" />
        <text name="google_id" data="1SjWRUl-D1FZ5fB2cy4jF4X9wTsQ5LWzo"/>
    </custom>

    <asset>
        <!-- arm models -->
        <mesh file="link0.stl"/>
        <mesh file="link1.stl"/>
        <mesh file="link1_cap.stl" />
        <mesh file="link1_connector.stl" />
        <mesh file="link2.stl" />
        <mesh file="link2_tube.stl" />
        <mesh file="link2_cap.stl" />
        <mesh file="link2_connector.stl" />
        <mesh file="link3a.stl" />
        <mesh file="link3a_connector.stl" />
        <mesh file="link3_tube.stl" />
        <mesh file="link3_cap.stl" />
        <mesh file="link3b.stl" />
        <mesh file="link3b_connector.stl" />
        <mesh file="link3b_connector2.stl"/>
        <mesh file="link4.stl" />
        <mesh file="link4_cap.stl" />
        <mesh file="link4_connector.stl" />
        <mesh file="link5.stl" />
        <mesh file="link5_cap.stl" />
        <mesh file="link5_connector.stl" />
        <mesh file="link6.stl" />
        <mesh file="link6_connector.stl" />

        <mesh file="FTS-300-S_support_20210305.stl" />
        <mesh file="robotiq_85_base_link.stl" />
        <mesh file="robotiq_85_finger_link.stl" />
        <mesh file="robotiq_85_finger_tip_link.stl" />
        <mesh file="robotiq_85_inner_knuckle_link.stl" />
        <mesh file="robotiq_85_knuckle_link.stl" />

        <material name="GriMat" specular="0.9" shininess="0.5" reflectance="0" rgba="0.1 0.1 0.1 1" emission="0.1" />

        <texture name="floor_tile" file="meshes/floor_tile.png" width="3000" height="3000" type="2d"/>
        <material name="tile"   texture="floor_tile" specular="0" shininess="0" reflectance="0" emission="1" />


        <material name="silver" specular="1" shininess="0.5" reflectance="1" emission="0.25" rgba="0.82 0.82 0.82 1"/>
        <material name="grey"   specular="1" shininess="0.5" reflectance="1" emission="0.1"  rgba="0.5 0.5 0.5 1"/>
        <material name="blue"   specular="1" shininess="0.5" reflectance="1" emission="0"    rgba="0.678 0.847 0.902 1"/>
        <material name="black"  specular="1" shininess="0.5" reflectance="1" emission="0"    rgba="0.2 0.2 0.2 1"/>
    </asset>

    <worldbody>
        <geom name="floor_grey_tile" pos="0 0 -0.001" size="1.0 1.0 0.05" type="plane" material="tile"/>

        <!-- light -->
        <light directional="true" pos="-0.5 0.5 3" dir="0 0 -1" />

        <!-- camera -->
        <camera name="camera1" mode= "fixed" euler="0 1.57 1.57" pos="1.0 0 0.3"/>
        <camera name="camera2" mode= "fixed" euler="-0.7 0 3.141592653589793" pos="0 1.2 1.2"/>
        <camera name="camera3" mode= "fixed" euler="0 0 3.141592653589793" pos="0 0.18 1.4"/>
        <!-- <camera name="camera4" mode= "fixed" euler="0 0 3.141592653589793" pos="0 0.18 1.4"/> -->


        <body name="base_link" pos="0 0 0">
            <geom name="link0" type="mesh" mesh="link0" pos="0 0 0"/>

            <body name="link1" pos="0 0 0.0213">
                <joint name="joint0" type="hinge" axis="0 0 1" pos="0 0 0" frictionloss="20"  damping="30" limited="true" range="-0.7853981633974483 0.7853981633974483"/>
                <inertial pos="0 -0.02561 0.00193" mass="3.761" diaginertia="0.1 0.1 0.1"/>
                <geom name="link1_connector"    type="mesh" mesh="link1_connector"  pos="0 0 0"         material="black" conaffinity="32" contype="32"/>
                <geom name="link1"              type="mesh" mesh="link1"            pos="0 0 0.008"     material="grey"/>
                <geom name="link1_cap"          type="mesh" mesh="link1_cap"        pos="0 0 .1025"     material="blue"/>


                <body name="link2" pos="-0.0663 0 0.0679">
                    <joint name="joint1" type="hinge" axis="-1 0 0" pos="0 0 0" frictionloss="20"  damping="30" limited="true" range="-0.7853981633974483 0.7853981633974483"/>
                    <inertial pos="-0.04706 0 0.2125" mass="8.058" diaginertia="0.1 0.1 0.1"/>
                    <geom name="link2_connector" type="mesh" mesh="link2_connector" pos="0 0 0"             material="black" conaffinity="32" contype="32"/>
                    <geom name="link2"           type="mesh" mesh="link2"           pos="-0.008 0 0"        material="grey"/>
                    <geom name="link2_cap"       type="mesh" mesh="link2_cap"       pos="-0.1015 0 -0.0025" material="blue"/>
                    <geom name="link2_tube"      type="mesh" mesh="link2_tube"      pos="-0.0679 0 0.066"   material="silver"/>


                    <body name="link3" pos="-0.008 0 0.425" quat="0.707107 -0.707107 0 0">
                        <joint name="joint2" type="hinge" axis="1 0 0" pos="0 0 0" frictionloss="20"  damping="30" limited="true" range="-0.7853981633974483 0.7853981633974483"/>
                        <inertial pos="0.0478 0 0.15" mass="2.846" diaginertia="0.1 0.1 0.1"/>
                        <geom name="link3a_connector"   type="mesh" mesh="link3a_connector"     pos="0 0 0"             material="black" conaffinity="32" contype="32"/>
                        <geom name="link3a"             type="mesh" mesh="link3a"               pos="0.008 0 0"         material="grey"/>
                        <geom name="link3_tube"         type="mesh" mesh="link3_tube"           pos="0.059 0 0.066"     material="silver"/>
                        <geom name="link3b_connector"   type="mesh" mesh="link3b_connector"     pos="0.059 0 0.3418"    material="black" />
                        <geom name="link3b_connector2"  type="mesh" mesh="link3b_connector2"    pos="0.059 0 0.34"      material="grey" conaffinity="32" contype="32"/>
                        <geom name="link3b"             type="mesh" mesh="link3b"               pos="0.059 0 0.347"     material="grey"/>
                        <geom name="link3_cap"          type="mesh" mesh="link3_cap"            pos="0.0837 0 0.392"    material="blue"/>


                        <body name="link4" pos="0.0173 0 0.3922" quat="0.707107 0.707107 0 0">
                            <joint name="joint3" type="hinge" axis="-1 0 0" pos="0 0 0" frictionloss="20"  damping="30" limited="true" range="0 1.5707963267948966"/>
                            <inertial pos="-0.05796 -0.0018 0" mass="1.37" diaginertia="0.1 0.1 0.1"/>
                            <geom name="link4_connector"    type="mesh" mesh="link4_connector"  pos="0 0 0"                 material="black" conaffinity="32" contype="32"/>
                            <geom name="link4"              type="mesh" mesh="link4"            pos="-0.008 0 0"            material="grey"/>
                            <geom name="link4_cap"          type="mesh" mesh="link4_cap"        pos="-0.05325 0 -0.0247"    material="blue"/>


                            <body name="link5" pos="-0.05325 0 0.04165" quat="0.707107 0 0 -0.707107">
                                <joint name="joint4" type="hinge" axis="0 0 1" pos="0 0 0" frictionloss="20"  damping="30" limited="true" range="-0.7853981633974483 0.7853981633974483"/>
                                <inertial pos="0.0018 0 0.01634" mass="1.3" diaginertia="0.1 0.1 0.1"/>
                                <geom name="link5_connector"    type="mesh" mesh="link5_connector"  pos="0 0 0"         material="black" conaffinity="32" contype="32"/>
                                <geom name="link5"              type="mesh" mesh="link5"            pos="0 0 0.0079"    material="grey"/>
                                <geom name="link5_cap"          type="mesh" mesh="link5_cap"        pos="0.025 0 0.053" material="blue"/>


                                <body name="link6" pos="-0.04165 0 0.05305">
                                    <joint name="joint5" type="hinge" axis="-1 0 0" pos="0 0 0" frictionloss="20"  damping="30" limited="true" range="-0.7853981633974483 0.7853981633974483"/>
                                    <inertial pos="-0.038841 0 0" mass="0.365" diaginertia="0.1 0.1 0.1"/>
                                    <geom name="link6_connector"    type="mesh" mesh="link6_connector"  pos="0 0 0"         material="black" conaffinity="32" contype="32"/>
                                    <geom name="link6"              type="mesh" mesh="link6"            pos="-0.008 0 0"    material="silver"/>
                                    <body name="EE" pos="-0.04 0 0" euler="0 0 0"/>


                                    <!-- <body name="gripper" pos="-0.04165 0 0.05305">
                                        <joint name="joint6" type="hinge" axis="-1 0 0" pos="0 0 0" frictionloss="20"  damping="30" limited="true" range="-0.7853981633974483 0.7853981633974483"/>
                                        <inertial pos="-0.038841 0 0" mass="0.365" diaginertia="0.1 0.1 0.1"/>
                                        <geom name="kinova_robotiq_coupler_mesh" type="mesh" mesh="kinova_robotiq_coupler" pos="0 0 0.0466" material="GriMat" />
                                        <body name="gg" pos="-0.04 0 0" euler="0 0 0"/>
                                    </body> -->


                                    <body name="gripper" pos="-0.025 0 0" quat="0.707107 0 -0.707107 0">
                                        <!-- <inertial pos="0 0.0823 0" quat="0.707107 -0.707107 0 0" mass="0" diaginertia="0 0 0" /> -->

                                        <!--camera name="gripper_camera" euler="0 3.14159265 0" fovy="63.5" /-->
                                        <!-- <geom name="light_1" type="sphere" size="0.005" pos="0.035 0 0.0166" material="Light" />
                                        <geom name="light_2" type="sphere" size="0.005" pos="-0.035 0 0.0166" material="Light" /> -->
                                        <!-- <geom name="FTS-300-S_support_20210305_mesh" type="mesh" mesh="FTS-300-S_support_20210305" pos="0 0 0" material="GriMat" /> -->

                                        <body name="robotiq_FT300_force_torque_senser" pos="0 0 0.05">
                                            <geom name="inner_cylinder" type="cylinder" pos="0 0 0.00325" size="0.0315 0.01875" material="GriMat"/>
                                            <geom name="outer_cylinder" type="cylinder" pos="0 0 0"       size="0.0375 0.0155"  material="GriMat" />
                                        </body>



                                        <!-- <geom name="robotiq_85_base_link_mesh" type="mesh" mesh="robotiq_85_base_link" pos="0 0 0.05" quat="0.707107 0 -0.707107 0" material="GriMat" /> -->

                                        <!-- <body name="right_driver" pos="0 -0.0306011 0.054904" quat="0.707107 0 -0.707107 0">
                                            <geom name="right_driver_mesh" type="mesh" mesh="robotiq_85_knuckle_link" material="GriMat" contype="0" conaffinity="0" />
                                            <joint name="joint7_1" axis="0 0 1" type="hinge" limited="true" range="0 0.872664626" />


                                            <body name="right_coupler" pos="0 -0.0315 0">
                                                <geom name="right_coupler_mesh" type="mesh" mesh="robotiq_85_finger_link" material="GriMat" contype="0" conaffinity="0" />
                                                <joint name="joint8_1" axis="0 0 1" type="hinge" limited="true" range="0 2.967059728" />

                                                <body name="right_follower_link" pos="0.0475 -0.006 0">
                                                    <geom name="right_follower_mesh" pos="0.0025 0.021 0" type="mesh" mesh="robotiq_85_finger_tip_link" material="GriMat" />
                                                    <joint name="joint9_1" axis="0 0 1" type="hinge" limited="true" range="0 2.967059728" />
                                                </body>

                                            </body>

                                        </body> -->

                                        <!-- <body name="right_spring_link" pos="0.0016 -0.012 0.0614" quat="0.707107 0 -0.707107 0">
                                            <geom name="right_spring_mesh" type="mesh" pos="0 -0.0005 0.0016" mesh="robotiq_85_inner_knuckle_link" material="GriMat" contype="0" conaffinity="0" />
                                            <joint name="joint10_1" axis="0 0 1" type="hinge" limited="true" range="0 1" />
                                        </body>


                                        <body name="left_driver" pos="0 0.0306011 0.054904" quat="0 0.707107 0 0.707107">
                                            <geom name="left_driver_mesh" type="mesh" mesh="robotiq_85_knuckle_link" material="GriMat" contype="0" conaffinity="0" />
                                            <joint name="joint7_2" axis="0 0 1" type="hinge" limited="true" range="0 0.872664626" />


                                            <body name="left_coupler" pos="0 -0.0315 0">
                                                <geom name="left_coupler_mesh" type="mesh" mesh="robotiq_85_finger_link" material="GriMat" contype="0" conaffinity="0" />
                                                <joint name="joint8_2" axis="0 0 1" type="hinge" limited="true" range="0 2.967059728" />

                                                <body name="left_follower_link" pos="0.0475 -0.006 0">
                                                    <geom name="left_follower_mesh" pos="0.0025 0.021 0" type="mesh" mesh="robotiq_85_finger_tip_link" material="GriMat" />
                                                    <joint name="joint9_2" axis="0 0 1" type="hinge" limited="true" range="0 2.967059728" />
                                                </body>

                                            </body>

                                        </body>

                                        <body name="left_spring_link" pos="0.0016 0.012 0.0614" quat="0 0.707107 0 0.707107">
                                            <geom name="left_spring_mesh" type="mesh" pos="0 0.0005 0.0016" mesh="robotiq_85_inner_knuckle_link" material="GriMat" contype="0" conaffinity="0" />
                                            <joint name="joint10_2" axis="0 0 1" type="hinge" limited="true" range="0 1" />
                                        </body> -->

                                    </body>


                                </body>
                            </body>
                        </body>
                    </body>
                </body>
            </body>
        </body>
    </worldbody>

    <actuator>
        <general name="joint0_actuator"  joint="joint0" ctrllimited="true" forcelimited="true" ctrlrange="-0.7853981633974483 0.7853981633974483" forcerange="-300 300" biastype="affine" gainprm="300 0 0" biasprm="0 -300 0" />
        <general name="joint1_actuator"  joint="joint1" ctrllimited="true" forcelimited="true" ctrlrange="-0.7853981633974483 0.7853981633974483" forcerange="-300 300" biastype="affine" gainprm="300 0 0" biasprm="0 -300 0" />
        <general name="joint2_actuator"  joint="joint2" ctrllimited="true" forcelimited="true" ctrlrange="-0.7853981633974483 0.7853981633974483" forcerange="-300 300" biastype="affine" gainprm="300 0 0" biasprm="0 -300 0" />
        <general name="joint3_actuator"  joint="joint3" ctrllimited="true" forcelimited="true" ctrlrange=" 0                  1.5707963267948966" forcerange="-300 300" biastype="affine" gainprm="300 0 0" biasprm="0 -300 0" />
        <general name="joint4_actuator"  joint="joint4" ctrllimited="true" forcelimited="true" ctrlrange="-0.7853981633974483 0.7853981633974483" forcerange="-300 300" biastype="affine" gainprm="300 0 0" biasprm="0 -300 0" />
        <general name="joint5_actuator"  joint="joint5" ctrllimited="true" forcelimited="true" ctrlrange="-0.7853981633974483 0.7853981633974483" forcerange="-300 300" biastype="affine" gainprm="300 0 0" biasprm="0 -300 0" />
    </actuator>

</mujoco>
